<sdf version='1.7'>
  <world name='default'>
    <light name='sun' type='directional'>
      <cast_shadows>1</cast_shadows>
      <pose>0 0 10 0 -0 0</pose>
      <diffuse>0.8 0.8 0.8 1</diffuse>
      <specular>0.2 0.2 0.2 1</specular>
      <attenuation>
        <range>1000</range>
        <constant>0.9</constant>
        <linear>0.01</linear>
        <quadratic>0.001</quadratic>
      </attenuation>
      <direction>-0.5 0.1 -0.9</direction>
      <spot>
        <inner_angle>0</inner_angle>
        <outer_angle>0</outer_angle>
        <falloff>0</falloff>
      </spot>
    </light>
    <model name='ground_plane'>
      <static>1</static>
      <link name='link'>
        <collision name='collision'>
          <geometry>
            <plane>
              <normal>0 0 1</normal>
              <size>100 100</size>
            </plane>
          </geometry>
          <surface>
            <friction>
              <ode>
                <mu>100</mu>
                <mu2>50</mu2>
              </ode>
              <torsional>
                <ode/>
              </torsional>
            </friction>
            <contact>
              <ode/>
            </contact>
            <bounce/>
          </surface>
          <max_contacts>10</max_contacts>
        </collision>
        <visual name='visual'>
          <cast_shadows>0</cast_shadows>
          <geometry>
            <plane>
              <normal>0 0 1</normal>
              <size>100 100</size>
            </plane>
          </geometry>
          <material>
            <script>
              <uri>file://media/materials/scripts/gazebo.material</uri>
              <name>Gazebo/Grey</name>
            </script>
          </material>
        </visual>
        <self_collide>0</self_collide>
        <enable_wind>0</enable_wind>
        <kinematic>0</kinematic>
      </link>
    </model>
    <gravity>0 0 -9.8</gravity>
    <magnetic_field>6e-06 2.3e-05 -4.2e-05</magnetic_field>
    <atmosphere type='adiabatic'/>
    <physics type='ode'>
      <max_step_size>0.001</max_step_size>
      <real_time_factor>1</real_time_factor>
      <real_time_update_rate>1000</real_time_update_rate>
    </physics>
    <scene>
      <ambient>0.4 0.4 0.4 1</ambient>
      <background>0.7 0.7 0.7 1</background>
      <shadows>1</shadows>
    </scene>
    <audio>
      <device>default</device>
    </audio>
    <wind/>
    <spherical_coordinates>
      <surface_model>EARTH_WGS84</surface_model>
      <latitude_deg>0</latitude_deg>
      <longitude_deg>0</longitude_deg>
      <elevation>0</elevation>
      <heading_deg>0</heading_deg>
    </spherical_coordinates>
    <state world_name='default'>
      <sim_time>426 625000000</sim_time>
      <real_time>282 491230283</real_time>
      <wall_time>1675786515 193526527</wall_time>
      <iterations>281669</iterations>
      <model name='container-multi-multi-stack'>
        <pose>-22.8923 4.96333 0 0 -0 0</pose>
        <scale>1 1 1</scale>
        <link name='chassis'>
          <pose>-22.8923 4.96333 0 0 -0 0</pose>
          <velocity>0 0 0 0 -0 0</velocity>
          <acceleration>0 0 0 0 -0 0</acceleration>
          <wrench>0 0 0 0 -0 0</wrench>
        </link>
      </model>
      <model name='ground_plane'>
        <pose>0 0 0 0 -0 0</pose>
        <scale>1 1 1</scale>
        <link name='link'>
          <pose>0 0 0 0 -0 0</pose>
          <velocity>0 0 0 0 -0 0</velocity>
          <acceleration>0 0 0 0 -0 0</acceleration>
          <wrench>0 0 0 0 -0 0</wrench>
        </link>
      </model>
      <model name='pallet_truck_diff'>
        <pose>-15.249 4.89618 0 0 -0.002668 -1.13605</pose>
        <scale>1 1 1</scale>
        <link name='robot_base_footprint'>
          <pose>-15.249 4.89618 0 0 -0.002668 -1.13605</pose>
          <velocity>0.000164 5.4e-05 0.00036 0.000968 -0.001643 4.2e-05</velocity>
          <acceleration>0.066611 0.14599 0.735347 -2.58696 0.97598 -0.77627</acceleration>
          <wrench>14.0639 30.8235 155.258 0 -0 0</wrench>
        </link>
        <link name='robot_battery_case_link'>
          <pose>-14.7033 3.72111 0.717459 -4e-06 -0.002667 -1.13605</pose>
          <velocity>-0.000785 -0.000564 7e-05 0.000805 -0.001177 4.1e-05</velocity>
          <acceleration>-0.877535 -0.585946 -0.276802 -0.863164 -1.40417 -2.93061</acceleration>
          <wrench>-87.7544 -58.5952 -27.6805 0 -0 0</wrench>
        </link>
        <link name='robot_diff_left_wheel_link'>
          <pose>-14.7088 3.49532 0.039998 -2.7e-05 1.24348 -1.13606</pose>
          <velocity>2e-06 -1.7e-05 -7e-05 0.00046 5.4e-05 -6.1e-05</velocity>
          <acceleration>0.007065 0.06052 -0.700116 -2.0939 -0.182666 -0.000637</acceleration>
          <wrench>0.070648 0.605205 -7.00116 0 -0 0</wrench>
        </link>
        <link name='robot_diff_right_wheel_link'>
          <pose>-14.5274 3.57956 0.039997 -1e-05 -0.571616 -1.13605</pose>
          <velocity>1.2e-05 -2.1e-05 0.000264 0.000577 0.000291 2.6e-05</velocity>
          <acceleration>0.094989 0.098355 -0.021472 -3.11069 1.17298 -0.004212</acceleration>
          <wrench>0.949889 0.983553 -0.214715 0 -0 0</wrench>
        </link>
        <link name='robot_front_left_wheel_link'>
          <pose>-14.3958 3.48628 0.040371 0 0.308052 -1.13605</pose>
          <velocity>0.00017 5.9e-05 0.000399 0.002206 -0.001093 4.9e-05</velocity>
          <acceleration>0.405813 0.361435 0.30839 -1.19596 1.04814 -2.93934</acceleration>
          <wrench>0.202907 0.180717 0.154195 0 -0 0</wrench>
        </link>
        <link name='robot_front_right_wheel_link'>
          <pose>-14.7223 3.33465 0.040371 0 0.307769 -1.13605</pose>
          <velocity>0.000177 4.3e-05 -0.000292 0.002204 -0.001092 4.8e-05</velocity>
          <acceleration>0.4323 0.293967 -1.35324 -1.19894 1.04172 -2.94211</acceleration>
          <wrench>0.21615 0.146983 -0.676618 0 -0 0</wrench>
        </link>
        <link name='robot_left_fork_link'>
          <pose>-14.7025 4.19643 0.054307 -6e-06 -0.002667 -1.13605</pose>
          <velocity>-9.2e-05 -5.7e-05 0.000357 0.000489 -0.000397 4e-05</velocity>
          <acceleration>-0.558827 -0.119406 0.648624 -0.114932 -0.544524 -3.03078</acceleration>
          <wrench>-11.1765 -2.38812 12.9725 0 -0 0</wrench>
        </link>
        <link name='robot_right_fork_link'>
          <pose>-15.0671 4.02712 0.054309 -9e-06 -0.002667 -1.13605</pose>
          <velocity>-0.000183 -0.000115 -2.4e-05 0.000418 -6.7e-05 2.8e-05</velocity>
          <acceleration>-0.993242 -0.437 0.320101 -0.293536 -0.20483 0.018879</acceleration>
          <wrench>-19.8648 -8.73999 6.40203 0 -0 0</wrench>
        </link>
      </model>
      <model name='unit_box'>
        <pose>-9.65152 -0.92559 0.499995 0 1e-05 0</pose>
        <scale>1 1 1</scale>
        <link name='link'>
          <pose>-9.65152 -0.92559 0.499995 0 1e-05 0</pose>
          <velocity>0 0 0 0 -0 0</velocity>
          <acceleration>0.010615 -0.006191 -9.78231 0.012424 0.021225 1.8e-05</acceleration>
          <wrench>0.010615 -0.006191 -9.78231 0 -0 0</wrench>
        </link>
      </model>
      <model name='unit_cylinder'>
        <pose>-11.1245 5.279 0.499993 -3e-06 -4e-06 -0</pose>
        <scale>1 1 1</scale>
        <link name='link'>
          <pose>-11.1245 5.279 0.499993 -3e-06 -4e-06 -0</pose>
          <velocity>0 0 0 0 -0 0</velocity>
          <acceleration>0 0 -9.8 0 -0 0</acceleration>
          <wrench>0 0 -9.8 0 -0 0</wrench>
        </link>
      </model>
      <light name='sun'>
        <pose>0 0 10 0 -0 0</pose>
      </light>
    </state>
    <gui fullscreen='0'>
      <camera name='user_camera'>
        <pose>36.3235 17.5872 22.431 0 0.499643 -2.907</pose>
        <view_controller>orbit</view_controller>
        <projection_type>perspective</projection_type>
      </camera>
    </gui>
    <model name='pallet_truck_diff'>
      <link name='robot_base_footprint'>
        <inertial>
          <pose>0.073273 0 0.057187 0 -0 0</pose>
          <mass>211.135</mass>
          <inertia>
            <ixx>2.10266</ixx>
            <ixy>0</ixy>
            <ixz>-5.26863</ixz>
            <iyy>24.547</iyy>
            <iyz>0</iyz>
            <izz>23.1438</izz>
          </inertia>
        </inertial>
        <collision name='robot_base_footprint_fixed_joint_lump__robot__lidar2D_1_link_collision'>
          <pose>1.7 0 0.19 0 -0 0</pose>
          <geometry>
            <cylinder>
              <length>0.02</length>
              <radius>0.0508</radius>
            </cylinder>
          </geometry>
          <surface>
            <contact>
              <ode/>
            </contact>
            <friction>
              <ode/>
              <torsional>
                <ode/>
              </torsional>
            </friction>
            <bounce/>
          </surface>
          <max_contacts>10</max_contacts>
        </collision>
        <collision name='robot_base_footprint_fixed_joint_lump__robot_front_case_link_collision_1'>
          <pose>1.2982 0 0.711 0 -0 0</pose>
          <geometry>
            <mesh>
              <scale>1 1 1</scale>
              <uri>file:///root/home/dev_ws/install/robot_sim_toolbox/share/robot_sim_toolbox/urdf/robots/pallet_truck_diff/models/front_case.stl</uri>
            </mesh>
          </geometry>
          <max_contacts>10</max_contacts>
          <surface>
            <contact>
              <ode/>
            </contact>
            <bounce/>
            <friction>
              <torsional>
                <ode/>
              </torsional>
              <ode/>
            </friction>
          </surface>
        </collision>
        <collision name='robot_base_footprint_fixed_joint_lump__robot_diff_middle_link_collision_2'>
          <pose>1.4982 0 0.036 1.5708 -0 0</pose>
          <geometry>
            <cylinder>
              <length>0.01</length>
              <radius>0.01</radius>
            </cylinder>
          </geometry>
          <max_contacts>10</max_contacts>
          <surface>
            <contact>
              <ode/>
            </contact>
            <bounce/>
            <friction>
              <torsional>
                <ode/>
              </torsional>
              <ode/>
            </friction>
          </surface>
        </collision>
        <collision name='robot_base_footprint_fixed_joint_lump__robot_left_fork_wheel_link_collision_3'>
          <pose>0 0.201 0.04 1.5708 -0 0</pose>
          <geometry>
            <sphere>
              <radius>0.04</radius>
            </sphere>
          </geometry>
          <surface>
            <contact>
              <ode/>
            </contact>
            <friction>
              <ode>
                <mu>0.005</mu>
                <mu2>0.005</mu2>
              </ode>
              <torsional>
                <ode/>
              </torsional>
            </friction>
            <bounce/>
          </surface>
          <max_contacts>10</max_contacts>
        </collision>
        <collision name='robot_base_footprint_fixed_joint_lump__robot_right_fork_wheel_link_collision_4'>
          <pose>0 -0.201 0.04 1.5708 -0 0</pose>
          <geometry>
            <sphere>
              <radius>0.04</radius>
            </sphere>
          </geometry>
          <surface>
            <contact>
              <ode/>
            </contact>
            <friction>
              <ode>
                <mu>0.005</mu>
                <mu2>0.005</mu2>
              </ode>
              <torsional>
                <ode/>
              </torsional>
            </friction>
            <bounce/>
          </surface>
          <max_contacts>10</max_contacts>
        </collision>
        <visual name='robot_base_footprint_fixed_joint_lump__robot__lidar2D_1_link_visual'>
          <pose>1.7 0 0.19 0 -0 0</pose>
          <geometry>
            <cylinder>
              <length>0.02</length>
              <radius>0.0508</radius>
            </cylinder>
          </geometry>
        </visual>
        <visual name='robot_base_footprint_fixed_joint_lump__robot_front_case_link_visual_1'>
          <pose>1.2982 0 0.711 0 -0 0</pose>
          <geometry>
            <mesh>
              <scale>1 1 1</scale>
              <uri>file:///root/home/dev_ws/install/robot_sim_toolbox/share/robot_sim_toolbox/urdf/robots/pallet_truck_diff/models/front_case.stl</uri>
            </mesh>
          </geometry>
        </visual>
        <visual name='robot_base_footprint_fixed_joint_lump__robot_diff_middle_link_visual_2'>
          <pose>1.4982 0 0.036 1.5708 -0 0</pose>
          <geometry>
            <cylinder>
              <length>0.01</length>
              <radius>0.01</radius>
            </cylinder>
          </geometry>
        </visual>
        <visual name='robot_base_footprint_fixed_joint_lump__robot_left_fork_wheel_link_visual_3'>
          <pose>0 0.201 0.04 0 -0 0</pose>
          <geometry>
            <sphere>
              <radius>0.04</radius>
            </sphere>
          </geometry>
          <material>
            <script>
              <name>Gazebo/Black</name>
              <uri>file://media/materials/scripts/gazebo.material</uri>
            </script>
          </material>
        </visual>
        <visual name='robot_base_footprint_fixed_joint_lump__robot_right_fork_wheel_link_visual_4'>
          <pose>0 -0.201 0.04 0 -0 0</pose>
          <geometry>
            <sphere>
              <radius>0.04</radius>
            </sphere>
          </geometry>
          <material>
            <script>
              <name>Gazebo/Black</name>
              <uri>file://media/materials/scripts/gazebo.material</uri>
            </script>
          </material>
        </visual>
        <sensor name='{name}_1' type='ray'>
          <always_on>1</always_on>
          <visualize>1</visualize>
          <update_rate>10</update_rate>
          <ray>
            <scan>
              <horizontal>
                <samples>480</samples>
                <resolution>1</resolution>
                <min_angle>-1.57</min_angle>
                <max_angle>1.57</max_angle>
              </horizontal>
              <vertical>
                <samples>1</samples>
                <min_angle>0</min_angle>
                <max_angle>0</max_angle>
              </vertical>
            </scan>
            <range>
              <min>0.3</min>
              <max>30</max>
              <resolution>0.015</resolution>
            </range>
            <noise>
              <type>gaussian</type>
              <mean>0</mean>
              <stddev>0.01</stddev>
            </noise>
          </ray>
          <plugin name='robot__lidar2D_1_controller' filename='libgazebo_ros_ray_sensor.so'>
            <ros>
              <namespace>robot_</namespace>
              <remapping>~/out:=/scan</remapping>
            </ros>
            <output_type>sensor_msgs/LaserScan</output_type>
            <frame_name>robot__lidar2D_1_link</frame_name>
          </plugin>
          <pose>1.7 0 0.19 0 -0 0</pose>
        </sensor>
        <self_collide>0</self_collide>
        <enable_wind>0</enable_wind>
        <kinematic>0</kinematic>
      </link>
      <joint name='robot_elevator_joint' type='prismatic'>
        <pose relative_to='robot_base_footprint'>1.2975 0 0.714 0 -0 0</pose>
        <parent>robot_base_footprint</parent>
        <child>robot_battery_case_link</child>
        <axis>
          <xyz>0 0 1</xyz>
          <limit>
            <lower>0</lower>
            <upper>0.106</upper>
            <effort>1000</effort>
            <velocity>0.1</velocity>
          </limit>
          <dynamics>
            <spring_reference>0</spring_reference>
            <spring_stiffness>0</spring_stiffness>
          </dynamics>
        </axis>
      </joint>
      <link name='robot_battery_case_link'>
        <pose relative_to='robot_elevator_joint'>0 0 0 0 -0 0</pose>
        <inertial>
          <pose>-0.200002 0 -0.350001 0 -0 0</pose>
          <mass>100.001</mass>
          <inertia>
            <ixx>6.56084</ixx>
            <ixy>0</ixy>
            <ixz>-1.67298e-05</ixz>
            <iyy>5.05673</iyy>
            <iyz>0</iyz>
            <izz>3.91089</izz>
          </inertia>
        </inertial>
        <collision name='robot_battery_case_link_collision'>
          <pose>0 0 0 0 -0 0</pose>
          <geometry>
            <mesh>
              <scale>1 1 1</scale>
              <uri>file:///root/home/dev_ws/install/robot_sim_toolbox/share/robot_sim_toolbox/urdf/robots/pallet_truck_diff/models/battery_case.stl</uri>
            </mesh>
          </geometry>
          <max_contacts>10</max_contacts>
          <surface>
            <contact>
              <ode/>
            </contact>
            <bounce/>
            <friction>
              <torsional>
                <ode/>
              </torsional>
              <ode/>
            </friction>
          </surface>
        </collision>
        <collision name='robot_battery_case_link_fixed_joint_lump__robot_battery_case_protection_link_collision_1'>
          <pose>-0.439 0 -0.42 0 -0 0</pose>
          <geometry>
            <box>
              <size>0.001 0.52 0.5204</size>
            </box>
          </geometry>
          <max_contacts>10</max_contacts>
          <surface>
            <contact>
              <ode/>
            </contact>
            <bounce/>
            <friction>
              <torsional>
                <ode/>
              </torsional>
              <ode/>
            </friction>
          </surface>
        </collision>
        <visual name='robot_battery_case_link_visual'>
          <pose>0 0 0 0 -0 0</pose>
          <geometry>
            <mesh>
              <scale>1 1 1</scale>
              <uri>file:///root/home/dev_ws/install/robot_sim_toolbox/share/robot_sim_toolbox/urdf/robots/pallet_truck_diff/models/battery_case.stl</uri>
            </mesh>
          </geometry>
        </visual>
        <self_collide>0</self_collide>
        <enable_wind>0</enable_wind>
        <kinematic>0</kinematic>
      </link>
      <joint name='robot_left_fork_joint' type='prismatic'>
        <pose relative_to='robot_battery_case_link'>-0.4325 0.201 -0.662 0 -0 0</pose>
        <parent>robot_battery_case_link</parent>
        <child>robot_left_fork_link</child>
        <axis>
          <xyz>1 0 0</xyz>
          <limit>
            <lower>0</lower>
            <upper>0</upper>
            <effort>1000</effort>
            <velocity>1</velocity>
          </limit>
          <dynamics>
            <spring_reference>0</spring_reference>
            <spring_stiffness>0</spring_stiffness>
          </dynamics>
        </axis>
      </joint>
      <link name='robot_left_fork_link'>
        <pose relative_to='robot_left_fork_joint'>0 0 0 0 -0 0</pose>
        <inertial>
          <pose>-0.58127 0 0.012941 0 -0 0</pose>
          <mass>20</mass>
          <inertia>
            <ixx>0.0433633</ixx>
            <ixy>0</ixy>
            <ixz>0</ixz>
            <iyy>1.83978</iyy>
            <iyz>0</iyz>
            <izz>1.87858</izz>
          </inertia>
        </inertial>
        <collision name='robot_left_fork_link_collision'>
          <pose>0 0 0 0 -0 0</pose>
          <geometry>
            <mesh>
              <scale>1 1 1</scale>
              <uri>file:///root/home/dev_ws/install/robot_sim_toolbox/share/robot_sim_toolbox/urdf/robots/pallet_truck_diff/models/single_fork.stl</uri>
            </mesh>
          </geometry>
          <max_contacts>10</max_contacts>
          <surface>
            <contact>
              <ode/>
            </contact>
            <bounce/>
            <friction>
              <torsional>
                <ode/>
              </torsional>
              <ode/>
            </friction>
          </surface>
        </collision>
        <visual name='robot_left_fork_link_visual'>
          <pose>0 0 0 0 -0 0</pose>
          <geometry>
            <mesh>
              <scale>1 1 1</scale>
              <uri>file:///root/home/dev_ws/install/robot_sim_toolbox/share/robot_sim_toolbox/urdf/robots/pallet_truck_diff/models/single_fork.stl</uri>
            </mesh>
          </geometry>
        </visual>
        <self_collide>0</self_collide>
        <enable_wind>0</enable_wind>
        <kinematic>0</kinematic>
      </link>
      <joint name='robot_right_fork_joint' type='prismatic'>
        <pose relative_to='robot_battery_case_link'>-0.4325 -0.201 -0.662 0 -0 0</pose>
        <parent>robot_battery_case_link</parent>
        <child>robot_right_fork_link</child>
        <axis>
          <xyz>1 0 0</xyz>
          <limit>
            <lower>0</lower>
            <upper>0</upper>
            <effort>1000</effort>
            <velocity>1</velocity>
          </limit>
          <dynamics>
            <spring_reference>0</spring_reference>
            <spring_stiffness>0</spring_stiffness>
          </dynamics>
        </axis>
      </joint>
      <link name='robot_right_fork_link'>
        <pose relative_to='robot_right_fork_joint'>0 0 0 0 -0 0</pose>
        <inertial>
          <pose>-0.58127 0 0.012941 0 -0 0</pose>
          <mass>20</mass>
          <inertia>
            <ixx>0.0433633</ixx>
            <ixy>0</ixy>
            <ixz>0</ixz>
            <iyy>1.83978</iyy>
            <iyz>0</iyz>
            <izz>1.87858</izz>
          </inertia>
        </inertial>
        <collision name='robot_right_fork_link_collision'>
          <pose>0 0 0 0 -0 0</pose>
          <geometry>
            <mesh>
              <scale>1 1 1</scale>
              <uri>file:///root/home/dev_ws/install/robot_sim_toolbox/share/robot_sim_toolbox/urdf/robots/pallet_truck_diff/models/single_fork.stl</uri>
            </mesh>
          </geometry>
          <max_contacts>10</max_contacts>
          <surface>
            <contact>
              <ode/>
            </contact>
            <bounce/>
            <friction>
              <torsional>
                <ode/>
              </torsional>
              <ode/>
            </friction>
          </surface>
        </collision>
        <visual name='robot_right_fork_link_visual'>
          <pose>0 0 0 0 -0 0</pose>
          <geometry>
            <mesh>
              <scale>1 1 1</scale>
              <uri>file:///root/home/dev_ws/install/robot_sim_toolbox/share/robot_sim_toolbox/urdf/robots/pallet_truck_diff/models/single_fork.stl</uri>
            </mesh>
          </geometry>
        </visual>
        <self_collide>0</self_collide>
        <enable_wind>0</enable_wind>
        <kinematic>0</kinematic>
      </link>
      <joint name='robot_diff_left_joint' type='revolute'>
        <pose relative_to='robot_base_footprint'>1.4982 -0.1 0.036 0 -0 0</pose>
        <parent>robot_base_footprint</parent>
        <child>robot_diff_left_wheel_link</child>
        <axis>
          <xyz>0 1 0</xyz>
          <limit>
            <effort>1000</effort>
            <velocity>100</velocity>
            <lower>-1e+16</lower>
            <upper>1e+16</upper>
          </limit>
          <dynamics>
            <damping>0</damping>
            <friction>0</friction>
            <spring_reference>0</spring_reference>
            <spring_stiffness>0</spring_stiffness>
          </dynamics>
        </axis>
      </joint>
      <link name='robot_diff_left_wheel_link'>
        <pose relative_to='robot_diff_left_joint'>0 0 0 0 -0 0</pose>
        <inertial>
          <pose>6.3e-05 0 0.000465 0 -0 0</pose>
          <mass>10</mass>
          <inertia>
            <ixx>0.0123333</ixx>
            <ixy>0</ixy>
            <ixz>0</ixz>
            <iyy>0.008</iyy>
            <iyz>0</iyz>
            <izz>0.0123333</izz>
          </inertia>
        </inertial>
        <collision name='robot_diff_left_wheel_link_collision'>
          <pose>0 0 0 1.5708 -0 0</pose>
          <geometry>
            <cylinder>
              <length>0.1</length>
              <radius>0.04</radius>
            </cylinder>
          </geometry>
          <surface>
            <contact>
              <ode>
                <kp>1e+08</kp>
                <kd>10</kd>
              </ode>
            </contact>
            <friction>
              <ode>
                <mu>0.8</mu>
                <mu2>0.8</mu2>
              </ode>
              <torsional>
                <ode/>
              </torsional>
            </friction>
            <bounce/>
          </surface>
          <max_contacts>10</max_contacts>
        </collision>
        <visual name='robot_diff_left_wheel_link_visual'>
          <pose>0 0 0 1.5708 -0 0</pose>
          <geometry>
            <cylinder>
              <length>0.1</length>
              <radius>0.04</radius>
            </cylinder>
          </geometry>
        </visual>
        <self_collide>0</self_collide>
        <enable_wind>0</enable_wind>
        <kinematic>0</kinematic>
      </link>
      <joint name='robot_diff_right_joint' type='revolute'>
        <pose relative_to='robot_base_footprint'>1.4982 0.1 0.036 0 -0 0</pose>
        <parent>robot_base_footprint</parent>
        <child>robot_diff_right_wheel_link</child>
        <axis>
          <xyz>0 1 0</xyz>
          <limit>
            <effort>1000</effort>
            <velocity>100</velocity>
            <lower>-1e+16</lower>
            <upper>1e+16</upper>
          </limit>
          <dynamics>
            <damping>0</damping>
            <friction>0</friction>
            <spring_reference>0</spring_reference>
            <spring_stiffness>0</spring_stiffness>
          </dynamics>
        </axis>
      </joint>
      <link name='robot_diff_right_wheel_link'>
        <pose relative_to='robot_diff_right_joint'>0 0 0 0 -0 0</pose>
        <inertial>
          <pose>6.3e-05 0 0.000465 0 -0 0</pose>
          <mass>10</mass>
          <inertia>
            <ixx>0.0123333</ixx>
            <ixy>0</ixy>
            <ixz>0</ixz>
            <iyy>0.008</iyy>
            <iyz>0</iyz>
            <izz>0.0123333</izz>
          </inertia>
        </inertial>
        <collision name='robot_diff_right_wheel_link_collision'>
          <pose>0 0 0 1.5708 -0 0</pose>
          <geometry>
            <cylinder>
              <length>0.1</length>
              <radius>0.04</radius>
            </cylinder>
          </geometry>
          <surface>
            <contact>
              <ode>
                <kp>1e+08</kp>
                <kd>10</kd>
              </ode>
            </contact>
            <friction>
              <ode>
                <mu>0.8</mu>
                <mu2>0.8</mu2>
              </ode>
              <torsional>
                <ode/>
              </torsional>
            </friction>
            <bounce/>
          </surface>
          <max_contacts>10</max_contacts>
        </collision>
        <visual name='robot_diff_right_wheel_link_visual'>
          <pose>0 0 0 1.5708 -0 0</pose>
          <geometry>
            <cylinder>
              <length>0.1</length>
              <radius>0.04</radius>
            </cylinder>
          </geometry>
        </visual>
        <self_collide>0</self_collide>
        <enable_wind>0</enable_wind>
        <kinematic>0</kinematic>
      </link>
      <joint name='robot_front_left_wheel_joint' type='revolute'>
        <pose relative_to='robot_base_footprint'>1.6382 0.18 0.036 0 -0 0</pose>
        <parent>robot_base_footprint</parent>
        <child>robot_front_left_wheel_link</child>
        <axis>
          <xyz>0 1 0</xyz>
          <limit>
            <effort>100</effort>
            <velocity>100</velocity>
            <lower>-1e+16</lower>
            <upper>1e+16</upper>
          </limit>
          <dynamics>
            <spring_reference>0</spring_reference>
            <spring_stiffness>0</spring_stiffness>
          </dynamics>
        </axis>
      </joint>
      <link name='robot_front_left_wheel_link'>
        <pose relative_to='robot_front_left_wheel_joint'>0 0 0 0 -0 0</pose>
        <inertial>
          <pose>0 0 0 0 -0 0</pose>
          <mass>0.5</mass>
          <inertia>
            <ixx>0.00064</ixx>
            <ixy>0</ixy>
            <ixz>0</ixz>
            <iyy>0.00064</iyy>
            <iyz>0</iyz>
            <izz>0.00064</izz>
          </inertia>
        </inertial>
        <collision name='robot_front_left_wheel_link_collision'>
          <pose>0 0 0 1.5708 -0 0</pose>
          <geometry>
            <sphere>
              <radius>0.03</radius>
            </sphere>
          </geometry>
          <surface>
            <contact>
              <ode/>
            </contact>
            <friction>
              <ode>
                <mu>0</mu>
                <mu2>0</mu2>
                <fdir1>1 0 0</fdir1>
              </ode>
              <torsional>
                <ode/>
              </torsional>
            </friction>
            <bounce/>
          </surface>
          <max_contacts>10</max_contacts>
        </collision>
        <visual name='robot_front_left_wheel_link_visual'>
          <pose>0 0 0 0 -0 0</pose>
          <geometry>
            <sphere>
              <radius>0.03</radius>
            </sphere>
          </geometry>
        </visual>
        <gravity>1</gravity>
        <self_collide>0</self_collide>
        <enable_wind>0</enable_wind>
        <kinematic>0</kinematic>
      </link>
      <joint name='robot_front_right_wheel_joint' type='revolute'>
        <pose relative_to='robot_base_footprint'>1.6382 -0.18 0.036 0 -0 0</pose>
        <parent>robot_base_footprint</parent>
        <child>robot_front_right_wheel_link</child>
        <axis>
          <xyz>0 1 0</xyz>
          <limit>
            <effort>100</effort>
            <velocity>100</velocity>
            <lower>-1e+16</lower>
            <upper>1e+16</upper>
          </limit>
          <dynamics>
            <spring_reference>0</spring_reference>
            <spring_stiffness>0</spring_stiffness>
          </dynamics>
        </axis>
      </joint>
      <link name='robot_front_right_wheel_link'>
        <pose relative_to='robot_front_right_wheel_joint'>0 0 0 0 -0 0</pose>
        <inertial>
          <pose>0 0 0 0 -0 0</pose>
          <mass>0.5</mass>
          <inertia>
            <ixx>0.00064</ixx>
            <ixy>0</ixy>
            <ixz>0</ixz>
            <iyy>0.00064</iyy>
            <iyz>0</iyz>
            <izz>0.00064</izz>
          </inertia>
        </inertial>
        <collision name='robot_front_right_wheel_link_collision'>
          <pose>0 0 0 1.5708 -0 0</pose>
          <geometry>
            <sphere>
              <radius>0.03</radius>
            </sphere>
          </geometry>
          <surface>
            <contact>
              <ode/>
            </contact>
            <friction>
              <ode>
                <mu>0</mu>
                <mu2>0</mu2>
                <fdir1>1 0 0</fdir1>
              </ode>
              <torsional>
                <ode/>
              </torsional>
            </friction>
            <bounce/>
          </surface>
          <max_contacts>10</max_contacts>
        </collision>
        <visual name='robot_front_right_wheel_link_visual'>
          <pose>0 0 0 0 -0 0</pose>
          <geometry>
            <sphere>
              <radius>0.03</radius>
            </sphere>
          </geometry>
        </visual>
        <gravity>1</gravity>
        <self_collide>0</self_collide>
        <enable_wind>0</enable_wind>
        <kinematic>0</kinematic>
      </link>
      <static>0</static>
      <plugin name='joint_states' filename='libgazebo_ros_joint_state_publisher.so'>
        <joint_name>robot_left_fork_joint</joint_name>
        <joint_name>robot_right_fork_joint</joint_name>
        <joint_name>robot_front_left_wheel_joint</joint_name>
        <joint_name>robot_front_right_wheel_joint</joint_name>
        <joint_name>robot_left_fork_wheel_joint</joint_name>
        <joint_name>robot_right_fork_wheel_joint</joint_name>
        <joint_name>robot_elevator_joint</joint_name>
        <joint_name>robot_diff_left_joint</joint_name>
        <joint_name>robot_diff_right_joint</joint_name>
        <update_rate>100.0</update_rate>
      </plugin>
      <plugin name='diff_drive' filename='libgazebo_ros_diff_drive.so'>
        <update_rate>100</update_rate>
        <num_wheel_pairs>1</num_wheel_pairs>
        <left_joint>robot_diff_right_joint</left_joint>
        <right_joint>robot_diff_left_joint</right_joint>
        <wheel_separation>0.2</wheel_separation>
        <wheel_diameter>0.08</wheel_diameter>
        <max_wheel_torque>100</max_wheel_torque>
        <max_wheel_acceleration>1.0</max_wheel_acceleration>
        <publish_odom>1</publish_odom>
        <odometry_topic>/odom</odometry_topic>
        <publish_odom_tf>1</publish_odom_tf>
        <publish_wheel_tf>0</publish_wheel_tf>
        <odometry_frame>odom</odometry_frame>
        <robot_base_frame>robot_base_footprint</robot_base_frame>
      </plugin>
      <pose>0 0 0 0 -0 1.57</pose>
    </model>
    <model name='unit_box'>
      <pose>-9.65153 -0.92559 0.5 0 -0 0</pose>
      <link name='link'>
        <inertial>
          <mass>1</mass>
          <inertia>
            <ixx>0.166667</ixx>
            <ixy>0</ixy>
            <ixz>0</ixz>
            <iyy>0.166667</iyy>
            <iyz>0</iyz>
            <izz>0.166667</izz>
          </inertia>
          <pose>0 0 0 0 -0 0</pose>
        </inertial>
        <collision name='collision'>
          <geometry>
            <box>
              <size>1 1 1</size>
            </box>
          </geometry>
          <max_contacts>10</max_contacts>
          <surface>
            <contact>
              <ode/>
            </contact>
            <bounce/>
            <friction>
              <torsional>
                <ode/>
              </torsional>
              <ode/>
            </friction>
          </surface>
        </collision>
        <visual name='visual'>
          <geometry>
            <box>
              <size>1 1 1</size>
            </box>
          </geometry>
          <material>
            <script>
              <name>Gazebo/Grey</name>
              <uri>file://media/materials/scripts/gazebo.material</uri>
            </script>
          </material>
        </visual>
        <self_collide>0</self_collide>
        <enable_wind>0</enable_wind>
        <kinematic>0</kinematic>
      </link>
    </model>
    <model name='unit_cylinder'>
      <pose>-11.1245 5.279 0.5 0 -0 0</pose>
      <link name='link'>
        <inertial>
          <mass>1</mass>
          <inertia>
            <ixx>0.145833</ixx>
            <ixy>0</ixy>
            <ixz>0</ixz>
            <iyy>0.145833</iyy>
            <iyz>0</iyz>
            <izz>0.125</izz>
          </inertia>
          <pose>0 0 0 0 -0 0</pose>
        </inertial>
        <collision name='collision'>
          <geometry>
            <cylinder>
              <radius>0.5</radius>
              <length>1</length>
            </cylinder>
          </geometry>
          <max_contacts>10</max_contacts>
          <surface>
            <contact>
              <ode/>
            </contact>
            <bounce/>
            <friction>
              <torsional>
                <ode/>
              </torsional>
              <ode/>
            </friction>
          </surface>
        </collision>
        <visual name='visual'>
          <geometry>
            <cylinder>
              <radius>0.5</radius>
              <length>1</length>
            </cylinder>
          </geometry>
          <material>
            <script>
              <name>Gazebo/Grey</name>
              <uri>file://media/materials/scripts/gazebo.material</uri>
            </script>
          </material>
        </visual>
        <self_collide>0</self_collide>
        <enable_wind>0</enable_wind>
        <kinematic>0</kinematic>
      </link>
    </model>
    <model name='container-multi-multi-stack'>
      <static>1</static>
      <link name='chassis'>
        <pose>0 0 0 0 -0 0</pose>
        <collision name='collision'>
          <geometry>
            <mesh>
              <uri>model://container-multi-multi-stack/containerstack2.dae</uri>
            </mesh>
          </geometry>
          <max_contacts>10</max_contacts>
          <surface>
            <contact>
              <ode/>
            </contact>
            <bounce/>
            <friction>
              <torsional>
                <ode/>
              </torsional>
              <ode/>
            </friction>
          </surface>
        </collision>
        <visual name='visual'>
          <geometry>
            <mesh>
              <uri>model://container-multi-multi-stack/containerstack2.dae</uri>
            </mesh>
          </geometry>
        </visual>
        <self_collide>0</self_collide>
        <enable_wind>0</enable_wind>
        <kinematic>0</kinematic>
      </link>
      <pose>-22.8923 4.96333 0 0 -0 0</pose>
    </model>
  </world>
</sdf>
